<mujoco model="laptop_close">


  <include file="../scene.xml"/>
  <include file="../airbot_play/airbot_play_options.xml"/>
  <include file="../airbot_play/airbot_play_dependencies.xml"/>
  <include file="../object/usb_camera_dependencies.xml"/>
  <compiler meshdir="../../meshes/" texturedir="../../textures/"/>
  <include file="../object/table_cloth_dependencies.xml"/>

  <default>
    <default class="obj_visual">
      <geom group="2" type="mesh" contype="0" conaffinity="0"/>
    </default>
    <default class="obj_collision">
      <geom group="3" condim="6" solimp="2 1 0.01" solref="0.001 10" friction="1 0.005 0.0001" type="mesh"/>
    </default>
  </default>

  <contact>
    <exclude body1='lp1' body2='lp2'/>
  </contact>

  <worldbody>

    <!-- ======= AITBOT PLAY ======= -->
    <body name="arm_pose" pos="0.3 0.92 0.71" euler="0 0 3.1416">
      <include file="../airbot_play/airbot_play.xml"/>
    </body>

    <!-- ======= EYE SIDE ======= -->
    <camera name="eye_side" fovy="72.02" pos="-0.324 0.697 1.02" xyaxes=" 0.828 -0.561 0.    0.394 0.582 0.702"/>

    <body name='lp1' pos="-0.025 0.925 0.7075" euler="0 0 3.1416">
      <body name='laptop_1' pos="0.01 0 0"/>
      <inertial pos="0 0 0" mass="0.35" diaginertia="0.0002 0.0002 0.0002" />
      <geom size="0.12 0.166 0.0075" pos="0 0 0" type="box" rgba="0.1 .1 .1 1"/>
      <site name="laptop_bottom_site" pos="-0.12 0 0" euler="0 0 3.1416" size='0.001' type='sphere'/>
      <body name='lp2' pos="0.12 0 0.0075">
        <body name='laptop_2' pos="-0.00 0 0.005"/>
        <joint axis='0 1 0' range="0 3.14" damping="0.002" frictionloss='1' />
        <inertial pos="0 0 0" mass="0.005" diaginertia="0.000002 0.000002 0.000002" />
        <geom size="0.12 0.166 0.005" pos="-0.12 0 0.0025" type="box" density="10" rgba="0.1 .1 .1 1"/>
        <site name="laptop_cam_site" pos="-0.24 0 0" euler="0 0 3.1416" size='0.001' type='sphere'/>
      </body>
    </body>
    
    <body name="cabinet" pos="0.915 0.58 0.01">
      <include file="../object/cabinet.xml"/>
    </body>

    <include file="../lab3_env.xml"/>

  </worldbody>

  <equality>
    <joint joint1='endleft' joint2='endright' polycoef='0 -1 0 0 0 '/>
  </equality>

  <actuator>
    <include file="../airbot_play/airbot_play_control.xml"/>
  </actuator>

  <sensor>
    <include file="../airbot_play/airbot_play_sensor.xml"/>
  </sensor>

  <keyframe>
    <key name="ready" qpos='
     -0.055 -0.547 0.905 1.599 -1.398 -1.599  0 0 
      1.33
      0 0'
      ctrl="-0.055 -0.547 0.905 1.599 -1.398 -1.599  0"
    />
  </keyframe>

</mujoco>
