<mujoco model="airbot">
  <include file="airbot_config.xml"/>

  <tendon>
    <fixed name='gripper_gear'>
      <joint joint='teacher_joint2' coef='-25'/>
      <joint joint='teacher_joint3' coef='25'/>
    </fixed>
  </tendon>

  <equality>
    <joint joint1='teacher_joint2' joint2='teacher_joint3' polycoef='0 -1 0 0 0 '/>
  </equality>

  <worldbody>
    <geom type="mesh" contype="0" conaffinity="0" group="1" density="0" rgba="0.75294 0.75294 0.75294 1" mesh="base_link"/>
    <body name="link1" pos="0 0 0.1117">
      <inertial pos="5.65823e-05 -0.00254686 -0.0260161" quat="0.425246 0.565393 0.444998 0.549067" mass="0.609" diaginertia="0.000363812 0.000296936 0.000260542"/>
      <joint name="joint1" pos="0 0 0" axis="0 0 1" range="-3.151 2.089" actuatorfrcrange="-12 12"/>
      <geom type="mesh" rgba="0.75294 0.75294 0.75294 1" mesh="link1"/>
      <body name="link2" quat="0.136004 0.135754 -0.693387 0.69447">
        <inertial pos="0.150315 0.00717305 0.00160325" quat="-0.0035835 0.712028 0.029484 0.701523" mass="0.902" diaginertia="0.00338951 0.00317972 0.000396151"/>
        <joint name="joint2" pos="0 0 0" axis="0 0 1" range="-2.963 0.181" actuatorfrcrange="-12 12"/>
        <geom type="mesh" rgba="0.75294 0.75294 0.75294 1" mesh="link2"/>
        <body name="link3" pos="0.27009 0 0" quat="0.55806 -0.000659484 0.000443518 0.8298">
          <inertial pos="2.8745e-05 0.110064 0.00426641" quat="0.536553 0.458503 -0.460051 0.538739" mass="0.683" diaginertia="0.00112874 0.0011117 0.000205631"/>
          <joint name="joint3" pos="0 0 0" axis="0 0 1" range="-0.094 3.161" actuatorfrcrange="-12 12"/>
          <geom type="mesh" rgba="0.75294 0.75294 0.75294 1" mesh="link3"/>
          <body name="link4" pos="8.2128e-05 0.29015 0" quat="0.499998 -0.5 -0.5 -0.500002">
            <inertial pos="-4.38752e-05 0.000502807 -0.020529" quat="0.57802 0.407764 0.553627 0.439452" mass="0.358" diaginertia="0.000140287 0.000111206 0.000110237"/>
            <joint name="joint4" pos="0 0 0" axis="0 0 1" range="-3.012 3.012" actuatorfrcrange="-3 3"/>
            <geom type="mesh" rgba="0.75294 0.75294 0.75294 1" mesh="link4"/>
            <body name="link5" quat="0.707105 0.707108 0 0">
              <inertial pos="0.000107256 0.0376096 0.000942839" quat="0.657602 0.251011 -0.249099 0.665209" mass="0.403" diaginertia="0.00016511 0.000143238 0.000137102"/>
              <joint name="joint5" pos="0 0 0" axis="0 0 1" range="-1.859 1.859" actuatorfrcrange="-3 3"/>
              <geom type="mesh" rgba="0.75294 0.75294 0.75294 1" mesh="link5"/>
              <body name="link6" pos="0 0.0864 0" quat="0.707105 0 0 0.707108">
                <inertial pos="0.0188026 1.32115e-05 -0.00666341" quat="0.448598 0.543393 0.551618 0.446319" mass="0.708363" diaginertia="0.000709492 0.000612339 0.000205881"/>
                <joint name="joint6" pos="0 0 0" axis="1 0 0" range="-3.017 3.017" actuatorfrcrange="-3 3"/>
                <geom type="mesh" rgba="0.75294 0.75294 0.75294 1" mesh="link6"/>
                <geom pos="0.0040002 0.0219004 -0.0221024" quat="0.707107 0 -0.707107 0" type="mesh" mesh="flange"/>
                <geom pos="0 0 0" quat="1 0 -5e-05 0" type="mesh" rgba="0.89804 0.91765 0.92941 1" mesh="e2bbase"/>
                <geom pos="0.0624 0 2.29208e-07" quat="1 0 -5e-05 0" type="mesh" rgba="0.69804 0.69804 0.69804 1" mesh="e2blink1"/>
                <body name="gripper_link2" pos="0.0603983 -0.01 0.017">
                  <inertial pos="0.0010232 0.0097229 -0.013637" quat="0.950779 -0.16563 0.106878 0.239086" mass="0.066736" diaginertia="3.09e-05 3.09e-05 3.09e-05"/>
                  <joint name="teacher_joint2" pos="0 0 0" axis="0 1 0" type="slide" range="0 0.02" actuatorfrcrange="-3 3"/>
                  <geom type="mesh" rgba="0.69804 0.69804 0.69804 1" mesh="e2blink2"/>
                </body>
                <body name="gripper_link3" pos="0.0603983 0.016511 -0.017">
                  <inertial pos="-0.00042716 0.0014213 -0.0034061" quat="0.832954 0.476947 0.107173 -0.259274" mass="0.055504" diaginertia="1.33333e-05 1.33333e-05 1.33333e-05"/>
                  <joint name="teacher_joint3" pos="0 0 0" axis="0 1 0" type="slide" range="-0.02 0" actuatorfrcrange="-3 3"/>
                  <geom type="mesh" rgba="0.69804 0.69804 0.69804 1" mesh="e2blink3"/>
                </body>
              </body>
            </body>
          </body>
        </body>
      </body>
    </body>
  </worldbody>

  <actuator>
    <position name="joint1_position"  ctrllimited="true" ctrlrange="-3.14 2.09"  joint="joint1"        kp="15.0" user="1" forcelimited="true" forcerange="-20 20"/>
    <position name="joint2_position"  ctrllimited="true" ctrlrange="-2.96 0.17"  joint="joint2"        kp="15.0" user="1" forcelimited="true" forcerange="-20 20"/>
    <position name="joint3_position"  ctrllimited="true" ctrlrange="-0.087 3.14" joint="joint3"        kp="15.0" user="1" forcelimited="true" forcerange="-20 20"/>
    <position name="joint4_position"  ctrllimited="true" ctrlrange="-2.96 2.96"  joint="joint4"        kp="2.5"  user="1" forcelimited="true" forcerange="-8 8"/>
    <position name="joint5_position"  ctrllimited="true" ctrlrange="-1.74 1.74"  joint="joint5"        kp="2.5"  user="1" forcelimited="true" forcerange="-8 8"/>
    <position name="joint6_position"  ctrllimited="true" ctrlrange="-3.14 3.14"  joint="joint6"        kp="2.5"  user="1" forcelimited="true" forcerange="-8 8"/>
    <position name='gripper_position' ctrllimited="true" ctrlrange="0. 1."       tendon='gripper_gear' kp="3"    user="1" forcelimited="true" forcerange="-1 1"/>

    <velocity name="joint1_velocity"  ctrllimited="true" ctrlrange="-6.283 6.283" joint="joint1"        kv="0.15"  user="1" forcelimited="true" forcerange="-20 20"/>
    <velocity name="joint2_velocity"  ctrllimited="true" ctrlrange="-6.283 6.283" joint="joint2"        kv="0.175" user="1" forcelimited="true" forcerange="-20 20"/>
    <velocity name="joint3_velocity"  ctrllimited="true" ctrlrange="-6.283 6.283" joint="joint3"        kv="0.15"  user="1" forcelimited="true" forcerange="-20 20"/>
    <velocity name="joint4_velocity"  ctrllimited="true" ctrlrange="-6.283 6.283" joint="joint4"        kv="0.05"  user="1" forcelimited="true" forcerange="-8 8"/>
    <velocity name="joint5_velocity"  ctrllimited="true" ctrlrange="-6.283 6.283" joint="joint5"        kv="0.15"  user="1" forcelimited="true" forcerange="-8 8"/>
    <velocity name="joint6_velocity"  ctrllimited="true" ctrlrange="-6.283 6.283" joint="joint6"        kv="0.05"  user="1" forcelimited="true" forcerange="-8 8"/>
    <velocity name='gripper_velocity' ctrllimited="true" ctrlrange="-6.283 6.283" tendon='gripper_gear' kv="0.05"  user="1" forcelimited="true" forcerange="-1 1"/>

    <motor name="joint1_motor"  ctrllimited="true" ctrlrange="-20 20" joint="joint1"        user="1" forcelimited="true" forcerange="-20 20"/>
    <motor name="joint2_motor"  ctrllimited="true" ctrlrange="-20 20" joint="joint2"        user="1" forcelimited="true" forcerange="-20 20"/>
    <motor name="joint3_motor"  ctrllimited="true" ctrlrange="-20 20" joint="joint3"        user="1" forcelimited="true" forcerange="-20 20"/>
    <motor name="joint4_motor"  ctrllimited="true" ctrlrange="-8 8"   joint="joint4"        user="1" forcelimited="true" forcerange="-8 8"/>
    <motor name="joint5_motor"  ctrllimited="true" ctrlrange="-8 8"   joint="joint5"        user="1" forcelimited="true" forcerange="-8 8"/>
    <motor name="joint6_motor"  ctrllimited="true" ctrlrange="-8 8"   joint="joint6"        user="1" forcelimited="true" forcerange="-8 8"/>
    <motor name='gripper_motor' ctrllimited="true" ctrlrange="-1 1"   tendon='gripper_gear' user="1" forcelimited="true" forcerange="-1 1"/>

  </actuator>

  <sensor>
    <jointpos name="joint1_pos" joint="joint1" />
    <jointpos name="joint2_pos" joint="joint2" />
    <jointpos name="joint3_pos" joint="joint3" />
    <jointpos name="joint4_pos" joint="joint4" />
    <jointpos name="joint5_pos" joint="joint5" />
    <jointpos name="joint6_pos" joint="joint6" />
    <tendonpos name="gripper_pos" tendon="gripper_gear" />
    <jointvel name="joint1_vel" joint="joint1" />
    <jointvel name="joint2_vel" joint="joint2" />
    <jointvel name="joint3_vel" joint="joint3" />
    <jointvel name="joint4_vel" joint="joint4" />
    <jointvel name="joint5_vel" joint="joint5" />
    <jointvel name="joint6_vel" joint="joint6" />
    <tendonvel name="gripper_vel" tendon="gripper_gear" />
    <jointactuatorfrc name="joint1_torque" joint="joint1" />
    <jointactuatorfrc name="joint2_torque" joint="joint2" />
    <jointactuatorfrc name="joint3_torque" joint="joint3" />
    <jointactuatorfrc name="joint4_torque" joint="joint4" />
    <jointactuatorfrc name="joint5_torque" joint="joint5" />
    <jointactuatorfrc name="joint6_torque" joint="joint6" />
    <jointactuatorfrc name="gripper_torque" joint="teacher_joint3" />
  </sensor>

</mujoco>
