<?xml version="1.0"?>
<!-- =================================================================================== -->
<!-- |    This document was autogenerated by xacro from /opt/airbot_controller/share/airbot_moveit_config/config/airbot.urdf.xacro | -->
<!-- |    EDITING THIS FILE BY HAND IS NOT RECOMMENDED                                 | -->
<!-- =================================================================================== -->
<robot xmlns:controller="http://playerstage.sourceforge.net/gazebo/xmlschema/#controller" xmlns:interface="http://playerstage.sourceforge.net/gazebo/xmlschema/#interface" xmlns:sensor="http://playerstage.sourceforge.net/gazebo/xmlschema/#sensor" name="airbot">

  <mujoco>
    <compiler balanceinertia="true" discardvisual="false" strippath="false"/>
  </mujoco>

  <link name="world" />
  <joint name="fixed_base" type="fixed">
    <origin rpy="0 0 0" xyz="0 0 0" />
    <parent link="world" />
    <child link="base_link" />
  </joint>

  <link name="base_link">
    <inertial>
      <origin rpy="0 0 0" xyz="-0.013241649 -0.0014483907 0.037394006"/>
      <mass value="0.683"/>
      <inertia ixx="0.00056691" ixy="7.5556E-06" ixz="1.0335E-06" iyy="0.00068606" iyz="7.7985E-07" izz="0.0010143"/>
    </inertial>
    <visual>
      <origin rpy="0 0 0" xyz="0 0 0"/>
      <geometry>
        <mesh filename="/Users/jiayufei/ws/DISCOVERSE/tmp/airbot_play_v3_1/collision/base_link.STL"/>
      </geometry>
      <material name="">
        <color rgba="0.75294 0.75294 0.75294 1"/>
      </material>
    </visual>
    <collision>
      <origin rpy="0 0 0" xyz="0 0 0"/>
      <geometry>
        <mesh filename="/Users/jiayufei/ws/DISCOVERSE/tmp/airbot_play_v3_1/collision/base_link.STL"/>
      </geometry>
    </collision>
  </link>
  <link name="link1">
    <inertial>
      <origin rpy="0 0 0" xyz="5.6582251E-05 -0.0025468634 -0.026016066"/>
      <mass value="0.609"/>
      <inertia ixx="0.00026059" ixy="-2.1857E-07" ixz="1.3032E-06" iyy="0.00035988" iyz="1.5738E-05" izz="0.00030082"/>
    </inertial>
    <visual>
      <origin rpy="0 0 0" xyz="0 0 0"/>
      <geometry>
        <mesh filename="/Users/jiayufei/ws/DISCOVERSE/tmp/airbot_play_v3_1/collision/link1.STL"/>
      </geometry>
      <material name="">
        <color rgba="0.75294 0.75294 0.75294 1"/>
      </material>
    </visual>
    <collision>
      <origin rpy="0 0 0" xyz="0 0 0"/>
      <geometry>
        <mesh filename="/Users/jiayufei/ws/DISCOVERSE/tmp/airbot_play_v3_1/collision/link1.STL"/>
      </geometry>
    </collision>
  </link>
  <joint name="joint1" type="revolute">
    <origin rpy="0 0 0" xyz="0 0 0.1117"/>
    <parent link="base_link"/>
    <child link="link1"/>
    <axis xyz="0 0 1"/>
    <limit effort="12" lower="-3.151" upper="2.089" velocity="0.5"/>
  </joint>
  <link name="link2">
    <inertial>
      <origin rpy="0 0 0" xyz="0.15031499 0.0071730548 0.0016032489"/>
      <mass value="0.902"/>
      <inertia ixx="0.00040289" ixy="-0.00012909" ixz="4.6597E-05" iyy="0.003174" iyz="9.7791E-06" izz="0.0033885"/>
    </inertial>
    <visual>
      <origin rpy="0 0 0" xyz="0 0 0"/>
      <geometry>
        <mesh filename="/Users/jiayufei/ws/DISCOVERSE/tmp/airbot_play_v3_1/collision/link2.STL"/>
      </geometry>
      <material name="">
        <color rgba="0.75294 0.75294 0.75294 1"/>
      </material>
    </visual>
    <collision>
      <origin rpy="0 0 0" xyz="0 0 0"/>
      <geometry>
        <mesh filename="/Users/jiayufei/ws/DISCOVERSE/tmp/airbot_play_v3_1/collision/link2.STL"/>
      </geometry>
    </collision>
  </link>
  <joint name="joint2" type="revolute">
    <origin rpy="-1.5691 -0.38673 3.1409" xyz="0 0 0"/>
    <parent link="link1"/>
    <child link="link2"/>
    <axis xyz="0 0 1"/>
    <limit effort="12" lower="-2.963" upper="0.181" velocity="0.5"/>
  </joint>
  <link name="link3">
    <inertial>
      <origin rpy="0 0 0" xyz="2.8745009E-05 0.11006382 0.0042664091"/>
      <mass value="0.683"/>
      <inertia ixx="0.0011117" ixy="2.9694E-07" ixz="-1.1205E-07" iyy="0.00022817" iyz="0.00014247" izz="0.0011062"/>
    </inertial>
    <visual>
      <origin rpy="0 0 0" xyz="0 0 0"/>
      <geometry>
        <mesh filename="/Users/jiayufei/ws/DISCOVERSE/tmp/airbot_play_v3_1/collision/link3.STL"/>
      </geometry>
      <material name="">
        <color rgba="0.75294 0.75294 0.75294 1"/>
      </material>
    </visual>
    <collision>
      <origin rpy="0 0 0" xyz="0 0 0"/>
      <geometry>
        <mesh filename="/Users/jiayufei/ws/DISCOVERSE/tmp/airbot_play_v3_1/collision/link3.STL"/>
      </geometry>
    </collision>
  </link>
  <joint name="joint3" type="revolute">
    <origin rpy="0 0.0015895 1.9575" xyz="0.27009 0 0"/>
    <parent link="link2"/>
    <child link="link3"/>
    <axis xyz="0 0 1"/>
    <limit effort="12" lower="-0.094" upper="3.161" velocity="0.5"/>
  </joint>
  <link name="link4">
    <inertial>
      <origin rpy="0 0 0" xyz="-4.3875215E-05 0.00050280749 -0.020529025"/>
      <mass value="0.358"/>
      <inertia ixx="0.00011024" ixy="6.4278E-09" ixz="-5.8907E-08" iyy="0.00013798" iyz="-7.8592E-06" izz="0.00011351"/>
    </inertial>
    <visual>
      <origin rpy="0 0 0" xyz="0 0 0"/>
      <geometry>
        <mesh filename="/Users/jiayufei/ws/DISCOVERSE/tmp/airbot_play_v3_1/collision/link4.STL"/>
      </geometry>
      <material name="">
        <color rgba="0.75294 0.75294 0.75294 1"/>
      </material>
    </visual>
    <collision>
      <origin rpy="0 0 0" xyz="0 0 0"/>
      <geometry>
        <mesh filename="/Users/jiayufei/ws/DISCOVERSE/tmp/airbot_play_v3_1/collision/link4.STL"/>
      </geometry>
    </collision>
  </link>
  <joint name="joint4" type="revolute">
    <origin rpy="-1.5708 -1.5708 0" xyz="8.2128E-05 0.29015 0"/>
    <parent link="link3"/>
    <child link="link4"/>
    <axis xyz="0 0 1"/>
    <limit effort="3" lower="-3.012" upper="3.012" velocity="1"/>
  </joint>
  <link name="link5">
    <inertial>
      <origin rpy="0 0 0" xyz="1.0725637E-04 0.037609585 0.00094283927"/>
      <mass value="0.403"/>
      <inertia ixx="0.00014324" ixy="-1.2363E-07" ixz="-1.6092E-07" iyy="0.00015285" iyz="1.3894E-05" izz="0.00014936"/>
    </inertial>
    <visual>
      <origin rpy="0 0 0" xyz="0 0 0"/>
      <geometry>
        <mesh filename="/Users/jiayufei/ws/DISCOVERSE/tmp/airbot_play_v3_1/collision/link5.STL"/>
      </geometry>
      <material name="">
        <color rgba="0.75294 0.75294 0.75294 1"/>
      </material>
    </visual>
    <collision>
      <origin rpy="0 0 0" xyz="0 0 0"/>
      <geometry>
        <mesh filename="/Users/jiayufei/ws/DISCOVERSE/tmp/airbot_play_v3_1/collision/link5.STL"/>
      </geometry>
    </collision>
  </link>
  <joint name="joint5" type="revolute">
    <origin rpy="1.5708 0 0" xyz="0 0 0"/>
    <parent link="link4"/>
    <child link="link5"/>
    <axis xyz="0 0 1"/>
    <limit effort="3" lower="-1.859" upper="1.859" velocity="1"/>
  </joint>
  <link name="link6">
    <inertial>
      <origin rpy="0 0 0" xyz="-0.022 0 0"/>
      <mass value="0.118"/>
      <inertia ixx="2.3175E-05" ixy="-8.0893E-10" ixz="-2.5166E-14" iyy="1.2978E-05" iyz="-2.9196E-09" izz="1.2976E-05"/>
    </inertial>
    <visual>
      <origin rpy="0 0 0" xyz="0 0 0"/>
      <geometry>
        <mesh filename="/Users/jiayufei/ws/DISCOVERSE/tmp/airbot_play_v3_1/collision/link6.STL"/>
      </geometry>
      <material name="">
        <color rgba="0.75294 0.75294 0.75294 1"/>
      </material>
    </visual>
    <collision>
      <origin rpy="0 0 0" xyz="0 0 0"/>
      <geometry>
        <mesh filename="/Users/jiayufei/ws/DISCOVERSE/tmp/airbot_play_v3_1/collision/link6.STL"/>
      </geometry>
    </collision>
  </link>
  <joint name="joint6" type="revolute">
    <origin rpy="0 0 1.5708" xyz="0 0.0864 0"/>
    <parent link="link5"/>
    <child link="link6"/>
    <axis xyz="1 0 0"/>
    <limit effort="3" lower="-3.017" upper="3.017" velocity="1"/>
  </joint>
  <link name="end_link"/>
  <joint name="end_joint" type="fixed">
    <origin rpy="0 0 0" xyz="0 0 0"/>
    <parent link="link6"/>
    <child link="end_link"/>
  </joint>
  <ros2_control name="sim_joint1" type="actuator">
    <hardware>
      <plugin>airbot_hardware_interface/SimMotorActuatorHardware</plugin>
      <param name="sim_interface">sim0</param>
      <param name="motor_id">1</param>
    </hardware>
    <joint name="joint1">
      <command_interface name="position"/>
      <command_interface name="velocity"/>
      <command_interface name="effort"/>
      <command_interface name="control_mode_command"/>
      <command_interface name="max_velocity_thres"/>
      <command_interface name="max_effort_thres"/>
      <command_interface name="mit_kp"/>
      <command_interface name="mit_kd"/>
      <state_interface name="position"/>
      <state_interface name="velocity"/>
      <state_interface name="effort"/>
      <state_interface name="motor_temperature"/>
      <state_interface name="mos_temperature"/>
      <state_interface name="error_id"/>
    </joint>
  </ros2_control>
  <ros2_control name="sim_joint2" type="actuator">
    <hardware>
      <plugin>airbot_hardware_interface/SimMotorActuatorHardware</plugin>
      <param name="sim_interface">sim0</param>
      <param name="motor_id">2</param>
    </hardware>
    <joint name="joint2">
      <command_interface name="position"/>
      <command_interface name="velocity"/>
      <command_interface name="effort"/>
      <command_interface name="control_mode_command"/>
      <command_interface name="max_velocity_thres"/>
      <command_interface name="max_effort_thres"/>
      <command_interface name="mit_kp"/>
      <command_interface name="mit_kd"/>
      <state_interface name="position"/>
      <state_interface name="velocity"/>
      <state_interface name="effort"/>
      <state_interface name="motor_temperature"/>
      <state_interface name="mos_temperature"/>
      <state_interface name="error_id"/>
    </joint>
  </ros2_control>
  <ros2_control name="sim_joint3" type="actuator">
    <hardware>
      <plugin>airbot_hardware_interface/SimMotorActuatorHardware</plugin>
      <param name="sim_interface">sim0</param>
      <param name="motor_id">3</param>
    </hardware>
    <joint name="joint3">
      <command_interface name="position"/>
      <command_interface name="velocity"/>
      <command_interface name="effort"/>
      <command_interface name="control_mode_command"/>
      <command_interface name="max_velocity_thres"/>
      <command_interface name="max_effort_thres"/>
      <command_interface name="mit_kp"/>
      <command_interface name="mit_kd"/>
      <state_interface name="position"/>
      <state_interface name="velocity"/>
      <state_interface name="effort"/>
      <state_interface name="motor_temperature"/>
      <state_interface name="mos_temperature"/>
      <state_interface name="error_id"/>
    </joint>
  </ros2_control>
  <ros2_control name="sim_joint4" type="actuator">
    <hardware>
      <plugin>airbot_hardware_interface/SimMotorActuatorHardware</plugin>
      <param name="sim_interface">sim0</param>
      <param name="motor_id">4</param>
    </hardware>
    <joint name="joint4">
      <command_interface name="position"/>
      <command_interface name="velocity"/>
      <command_interface name="effort"/>
      <command_interface name="control_mode_command"/>
      <command_interface name="max_velocity_thres"/>
      <command_interface name="max_effort_thres"/>
      <command_interface name="mit_kp"/>
      <command_interface name="mit_kd"/>
      <state_interface name="position"/>
      <state_interface name="velocity"/>
      <state_interface name="effort"/>
      <state_interface name="motor_temperature"/>
      <state_interface name="mos_temperature"/>
      <state_interface name="error_id"/>
    </joint>
  </ros2_control>
  <ros2_control name="sim_joint5" type="actuator">
    <hardware>
      <plugin>airbot_hardware_interface/SimMotorActuatorHardware</plugin>
      <param name="sim_interface">sim0</param>
      <param name="motor_id">5</param>
    </hardware>
    <joint name="joint5">
      <command_interface name="position"/>
      <command_interface name="velocity"/>
      <command_interface name="effort"/>
      <command_interface name="control_mode_command"/>
      <command_interface name="max_velocity_thres"/>
      <command_interface name="max_effort_thres"/>
      <command_interface name="mit_kp"/>
      <command_interface name="mit_kd"/>
      <state_interface name="position"/>
      <state_interface name="velocity"/>
      <state_interface name="effort"/>
      <state_interface name="motor_temperature"/>
      <state_interface name="mos_temperature"/>
      <state_interface name="error_id"/>
    </joint>
  </ros2_control>
  <ros2_control name="sim_joint6" type="actuator">
    <hardware>
      <plugin>airbot_hardware_interface/SimMotorActuatorHardware</plugin>
      <param name="sim_interface">sim0</param>
      <param name="motor_id">6</param>
    </hardware>
    <joint name="joint6">
      <command_interface name="position"/>
      <command_interface name="velocity"/>
      <command_interface name="effort"/>
      <command_interface name="control_mode_command"/>
      <command_interface name="max_velocity_thres"/>
      <command_interface name="max_effort_thres"/>
      <command_interface name="mit_kp"/>
      <command_interface name="mit_kd"/>
      <state_interface name="position"/>
      <state_interface name="velocity"/>
      <state_interface name="effort"/>
      <state_interface name="motor_temperature"/>
      <state_interface name="mos_temperature"/>
      <state_interface name="error_id"/>
    </joint>
  </ros2_control>
</robot>
